Workbook
Name ФЦТруд: 'По ценностям адекват'!$I:$I
Name ФБКоманда: 'По благополучателям адекват'!$E:$E
Name ЧастныеблагаВнутренние: 'По благам'!$D:$D
Name Фокуснаблагах: 'По благам'!$A:$A
Name ЧастныеблагасобщественнымэффектомВнутренние: 'По благам'!$F:$F
Name ФБСообщество: 'По благополучателям адекват'!$C:$C
Name ФССоциальнаясфера: 'По секторам'!$F:$F
Name Фокуснаблагополучателе: #REF!
Name ЧастныеблагаИнструментальные: 'По благам'!$C:$C
Name ФЦДостоинство: 'По ценностям адекват'!$B:$B
Name ФЦСемья: 'По ценностям адекват'!$H:$H
Name ФББизнес: 'По благополучателям адекват'!$D:$D
Name ФСОбразование: 'По секторам'!$C:$C
Name ФЦСправедливость: 'По ценностям адекват'!$M:$M
Name ФСГородскаясреда: 'По секторам'!$H:$H
Name ФЦГражданственность: 'По ценностям адекват'!$E:$E
Name ФЦВзаимопомощь: 'По ценностям адекват'!$O:$O
Name ОбщественныеблагаИнструментальные: 'По благам'!$G:$G
Name ФЦИдеалы: 'По ценностям адекват'!$G:$G
Name ФЦПриоритет: 'По ценностям адекват'!$J:$J
Name ФБлага: 'По благам'!$B:$B
Name ФСЭкономика: 'По секторам'!$B:$B
Name ФСЭкология: 'По секторам'!$E:$E
Name ФБЛюди: 'По благополучателям адекват'!$A:$A
Name ФЦГуманизм: 'По ценностям адекват'!$K:$K
Name ФЦСлужение: 'По ценностям адекват'!$F:$F
Name ФСМестноеразвитие: 'По секторам'!$G:$G
Name ФЦМилосердие: 'По ценностям адекват'!$L:$L
Name ФЦПрава: 'По ценностям адекват'!$C:$C
Name ФЦКоллективизм: 'По ценностям адекват'!$N:$N
Name ОбщественныеблагаВнутренние: 'По благам'!$H:$H
Name ФБСемьи: 'По благополучателям адекват'!$B:$B
Name Фокуснаценностях: #REF!
Name ФЦЖизнь: 'По ценностям адекват'!$A:$A
Name ФЦЕдинство: 'По ценностям адекват'!$Q:$Q
Name Фокуснасекторе: 'По секторам'!$A:$A
Name ФСЗдоровье: 'По секторам'!$D:$D
Name ЧастныеблагасобщественнымэффектомИнструментальные: 'По благам'!$E:$E
Name ФЦПамять: 'По ценностям адекват'!$P:$P
Name ФСКультура: 'По секторам'!$I:$I
Name ФЦПатриотизм: 'По ценностям адекват'!$D:$D

Sheet Поиск
A2: Подход | D2: Область влияния | G2: Результат | K2: Результат | L2: Ценности | M2: Примеры показателей
A3: Фокус на секторе | B3: =IF(IFERROR(SEARCH("благополучателе", A3) > 0, FALSE), "Фокуснаблагополучателе", IF(IFERROR(SEARCH("секторе", A3) > 0, FALSE), "Фокуснасекторе", IF(IFERROR(SEARCH("благах", A3) > 0, FALSE), "Фокуснаблагах", IF(IFERROR(SEARCH("ценностях", A3) > 0, FALSE), "Фокуснаценностях","")))) -> Фокуснасекторе | C3: {=INDIRECT(B3)} -> Экономика | D3: Сообщество, общественность, широкая публика | E3: =IF(IFERROR(SEARCH("публика", D3) > 0, FALSE), "ФБСообщество", IF(IFERROR(SEARCH("люди", D3) > 0, FALSE), "ФБЛюди", IF(IFERROR(SEARCH("семьи", D3) > 0, FALSE), "ФБСемьи", IF(IFERROR(SEARCH("правительство", D3) > 0, FALSE), "ФББизнес", IF(IFERROR(SEARCH("команда", D3) > 0, FALSE), "ФБКоманда", IF(IFERROR(SEARCH("экономика", D3) > 0, FALSE), "ФСЭкономика", IF(IFERROR(SEARCH("образование", D3) > 0, FALSE), "ФСОбразование",IF(IFERROR(SEARCH("здоровье", D3) > 0, FALSE), "ФСЗдоровье",IF(IFERROR(SEARCH("экология", D3) > 0, FALSE), "ФСЭкология", IF(IFERROR(SEARCH("сфера", D3) > 0, FALSE), "ФССоциальнаясфера", IF(IFERROR(SEARCH("развитие", D3) > 0, FALSE), "ФСМестноеразвитие", IF(IFERROR(SEARCH("среда", D3) > 0, FALSE), "ФСГородскаясреда",IF(IFERROR(SEARCH("культура", D3) > 0, FALSE), "ФСКультура", IF(IFERROR(SEARCH("блага", D3) > 0, FALSE), "ФБлага", IF(IFERROR(SEARCH("достоинство", D3) > 0, FALSE), "ФЦДостоинство", IF(IFERROR(SEARCH("жизнь", D3) > 0, FALSE), "ФЦЖизнь", IF(IFERROR(SEARCH("права", D3) > 0, FALSE), "ФЦПрава", IF(IFERROR(SEARCH("патриотизм", D3) > 0, FALSE), "ФЦПатриотизм", IF(IFERROR(SEARCH("гражданственность", D3) > 0, FALSE), "ФЦГражданственность", IF(IFERROR(SEARCH("идеалы", D3) > 0, FALSE), "ФЦИдеалы", IF(IFERROR(SEARCH("семья", D3) > 0, FALSE), "ФЦСемья", IF(IFERROR(SEARCH("труд", D3) > 0, FALSE), "ФЦТруд", IF(IFERROR(SEARCH("приоритет", D3) > 0, FALSE), "ФЦПриоритет", IF(IFERROR(SEARCH("гуманизм", D3) > 0, FALSE), "ФЦГуманизм", IF(IFERROR(SEARCH("милосердие", D3) > 0, FALSE), "ФЦМилосердие", IF(IFERROR(SEARCH("справедливость", D3) > 0, FALSE), "ФЦСправедливость", IF(IFERROR(SEARCH("коллективизм", D3) > 0, FALSE), "ФЦКоллективизм", IF(IFERROR(SEARCH("взаимопомощь", D3) > 0, FALSE), "ФЦВзаимопомощь", IF(IFERROR(SEARCH("память", D3) > 0, FALSE), "ФЦПамять", IF(IFERROR(SEARCH("единство", D3) > 0, FALSE), "ФЦЕдинство", IF(IFERROR(SEARCH("служение", D3) > 0, FALSE), "ФЦСлужение",""))))))))))))))))))))))))))))))) -> ФБСообщество | F3: {=INDIRECT(E3)} -> Сообщество, общественность, широкая публика | G3: Сохранение наследия | H3: =IF(D3="Частные блага","Частныеблага", IF(D3="Частные блага с общественным эффектом", "Частныеблагасобщественнымэффектом", IF(D3="Общественные блага", "Общественныеблага",""))) | I3: =H3&G3 -> Сохранение наследия | J3: {=INDIRECT(I3)} -> #REF! | L3: =IFERROR(VLOOKUP(IF(ISBLANK(K3), G3, K3), 'Показатели'!A:D, 2, FALSE), "") -> Историческая память и преемственность поколений | M3: =IFERROR(VLOOKUP(IF(ISBLANK(K3), G3, K3), 'Показатели'!A:D, 3, FALSE), "") -> Количество отреставрированных предметов/документов. | N3: =IFERROR(VLOOKUP(IF(ISBLANK(K3), G3, K3), 'Показатели'!A:D, 4, FALSE), "") -> Рост индекса осведомленности о наследии (опрос).
C4: Образование | F4: Расширение участия
C5: Здоровье | F5: Сохранение наследия
C6: Экология | F6: Повышение уровня знаний в обществе
C7: Социальная сфера | F7: Укрепление социального капитала
C8: Местное развитие | F8: Содействие развитию сообщества
C9: Городская среда | F9: Формирование идентичности и узнаваемости
C10: Культура

Sheet По художественной ценности
A1: Результат | B1: Подвид | C1: Ценности | D1: Показатель 1 | E1: Показатель 2 (опционально)

Sheet По благам дополнительно
A1: Результат | B1: Вид блага | C1: Инструментальные /Внутренние | D1: Ценности | E1: Показатель 1 | F1: Показатель 2 (опционально)
A2: Повышение уровня знаний | B2: Частные | C2: Инструментальные
A3: Улучшенные навыки коммуникации | B3: Частные | C3: Инструментальные
A4: Вдохновение | B4: Частные | C4: Внутренние
A5: Удовольствие | B5: Частные | C5: Внутренние
A6: Достоинство | B6: Частные | C6: Внутренние
A7: Расширение участия | B7: Частные с общественным эффектом | C7: Инструментальные
A8: Повышение самоэффективности | B8: Частные с общественным эффектом | C8: Инструментальные
A9: Повышение навыков обучения | B9: Частные с общественным эффектом | C9: Инструментальные
A10: Расширенная способность к сопереживанию | B10: Частные с общественным эффектом | C10: Внутренние
A11: Расширенная способность к саморефлексии | B11: Частные с общественным эффектом | C11: Внутренние
A12: Когнитивный рост | B12: Частные с общественным эффектом | C12: Внутренние
A13: Формирование идентичности | B13: Частные с общественным эффектом | C13: Внутренние
... A22: Сохранение наследия | B22: Общественные | C22: Внутренние

Sheet По ценностям адекват
A1: Жизнь | B1: Достоинство | C1: Права и свободы человека | D1: Патриотизм | E1: Гражданственность | F1: Служение Отечеству и ответственность за его судьбу | G1: Высокие нравственные идеалы | H1: Крепкая семья | I1: Созидательный труд | J1: Приоритет духовного над материальным | K1: Гуманизм | L1: Милосердие | M1: Справедливость | N1: Коллективизм | O1: Взаимопомощь и взаимоуважение | P1: Историческая память и преемственность поколений | Q1: Единство народов России
A2: Ответственное отношение к своему здоровью | B2: Возможности самореализации | C2: Развитие гражданского участия, вовлеченности | D2: Увеличение числа граждан (молодежи), стремящихся жить и работать на родине | E2: Развитие гражданского участия, вовлеченности | F2: Укрепление единства и сплоченности общества на основе гражданской идентичности, сохранение духовно-нравственных ценностей | G2: Качественный рост культурных и досуговых запросов граждан, в том числе в отношении медиапродукции | H2: Рост общественной ценности и повышение статуса семьи | I2: Увеличилась трудовая мобильность работников сферы искусства (в т. ч. студентов профильных ВУЗов) из центров в регионы | J2: Cпособность понимать и ценить искусство и культуру | K2: Изменение чувства валидированности (не стигматизированности) | L2: Развитие эмоционального интеллекта | M2: Изменение чувства валидированности (не стигматизированности) | N2: Консолидация местного сообщества | O2: Изменение понимания/ ожиданий возможностей самореализации | P2: Консолидация местного сообщества | Q2: Национальная идентичность / развитие межнациональных / межкультурных связей
A3: Мотивация активного образа жизни | B3: Повышение удовлетворенностью жизнью | C3: Изменение чувства валидированности (не стигматизированности) | D3: Укрепление единства и сплоченности общества на основе гражданской идентичности, сохранение духовно-нравственных ценностей | E3: Рост социального капитала | F3: Консолидация местного сообщества | G3: Укрепление единства и сплоченности общества на основе гражданской идентичности, сохранение духовно-нравственных ценностей | H3: Обеспечение условий для развлечений, удовольствий, радости | I3: Развитие рынка труда в сфере культуры | J3: Повышение социокультурного потенциала общества | K3: Развитие эмоционального интеллекта | L3: Изменение чувства валидированности (не стигматизированности) | M3: Доступность среды | N3: Развитие контактов между поколениями | O3: Развитие эмоционального интеллекта | P3: Понимание себя как части культуры, общества | Q3: Гармонизация социально-экономического развития регионов страны, особенно малых городов и сельских поселений
B4: Поддержка людей в том, чтобы позитивно встречать риски | C4: Изменение чувства безопасности | D4: Вклад в личностное развитие | E4: Вклад в личностное развитие | F4: Гармонизация социально-экономического развития регионов страны, особенно малых городов и сельских поселений | H4: Обеспечение возможности отвлечения от повседневных забот | I4: Рост цифровизации сферы культуры и искусства | J4: Укрепление единства и сплоченности общества на основе гражданской идентичности, сохранение духовно-нравственных ценностей | K4: Развитие контактов между поколениями | M4: Безопасность среды | N4: Развитие сообщества творческих профессионалов | O4: Изменение чувства валидированности (не стигматизированности) | P4: Развитие контактов между поколениями
B5: Повышение общей удовлетворенности жизнью через самовыражение | C5: Увеличение числа граждан (молодежи), стремящихся жить и работать на родине | D5: Изменение отношения к культуре, обществу, наследию, экологии … | E5: Изменение отношения к культуре, обществу, наследию, экологии … | F5: Вовлечение жителей в процесс развития региона | I5: Развитие сообщества творческих профессионалов | J5: Качественный рост культурных и досуговых запросов граждан, в том числе в отношении медиапродукции | K5: Рост социального капитала | M5: Освоенность общественных зон | P5: Владение русским литературным языком, знание истории страны
B6: Изменение чувства валидированности (не стигматизированности) | C6: Активизация культурного потенциала территорий | E6: Развитие лидерских качеств | F6: Вклад в экономическое благополучие региона | J6: Обогащение культурно-интеллектуального досуга жителей и гостей
B7: Повышение эффектов благополучия (стресс, самооценка, уверенность, удовольствие…) | E7: Расширение участия в социальной деятельности | J7: Расширение пользовательского и культурного опыта жителей за счет участия в событиях различных форматов
E8: Содействие людям в исследовании своих ценностей, смыслов и мечтаний | J8: Повышение ожиданий публики от уровня культурных событий в городе в целом, интерес к новым именам (расширение кругозора и мотивации)
E9: Укрепление единства и сплоченности общества на основе гражданской идентичности, сохранение духовно-нравственных ценностей | J9: Повышение знаний и актуализация представления о современной культурной, образовательной, литературной повестках России
E10: Консолидация местного сообщества
E11: Понимание себя как части культуры, общества

Sheet Поиск (копия)
A2: Подход | D2: Область влияния | G2: Тип результата/Результат | K2: Результат | L2: Показатель
A3: Фокус на благополучателе | B3: =IF(IFERROR(SEARCH("благополучателе", A3) > 0, FALSE), "Фокуснаблагополучателе", IF(IFERROR(SEARCH("секторе", A3) > 0, FALSE), "Фокуснасекторе", IF(IFERROR(SEARCH("благах", A3) > 0, FALSE), "Фокуснаблагах",""))) -> Фокуснаблагополучателе | C3: {=INDIRECT(B3)} -> #REF! | D3: Отдельные люди | E3: =IF(IFERROR(SEARCH("публика", D3) > 0, FALSE), "ФБСообщество", IF(IFERROR(SEARCH("люди", D3) > 0, FALSE), "ФБЛюди", IF(IFERROR(SEARCH("семьи", D3) > 0, FALSE), "ФБСемьи", IF(IFERROR(SEARCH("правительство", D3) > 0, FALSE), "ФББизнес", IF(IFERROR(SEARCH("команда", D3) > 0, FALSE), "ФБКоманда", IF(IFERROR(SEARCH("экономика", D3) > 0, FALSE), "ФСЭкономика", IF(IFERROR(SEARCH("образование", D3) > 0, FALSE), "ФСОбразование",IF(IFERROR(SEARCH("здоровье", D3) > 0, FALSE), "ФСЗдоровье",IF(IFERROR(SEARCH("экология", D3) > 0, FALSE), "ФСЭкология", IF(IFERROR(SEARCH("сфера", D3) > 0, FALSE), "ФССоциальнаясфера", IF(IFERROR(SEARCH("развитие", D3) > 0, FALSE), "ФСМестноеразвитие", IF(IFERROR(SEARCH("среда", D3) > 0, FALSE), "ФСГородскаясреда",IF(IFERROR(SEARCH("культура", D3) > 0, FALSE), "ФСКультура", IF(IFERROR(SEARCH("блага", D3) > 0, FALSE), "ФБлага","")))))))))))))) -> ФБЛюди | F3: {=INDIRECT(E3)} -> Отдельные люди | G3: Вклад в личностное развитие | H3: =IF(D3="Частные блага","Частныеблага", IF(D3="Частные блага с общественным эффектом", "Частныеблагасобщественнымэффектом", IF(D3="Общественные блага", "Общественныеблага",""))) | I3: =H3&G3 -> Вклад в личностное развитие | J3: {=INDIRECT(I3)} -> #REF! | L3: =IFERROR(VLOOKUP(IF(ISBLANK(K3), G3, K3), 'Показатели'!A:D, 2, FALSE), "") -> Патриотизм, Гражданственность, Высокие нравственные идеалы, Приоритет духовного над материальным, Взаимопомощь и взаимоуважение
F4: Вклад в личностное развитие
F5: Развитие эмоционального интеллекта
F6: Повышение самоэффективности,
F7: Повышение навыков обучения
F8: Изменение понимания/ ожиданий возможностей самореализации
F9: Изменение отношения к культуре, обществу, наследию, экологии …
F10: Изменение знаний и навыков
F11: Изменение поведения
F12: Повышение общей удовлетворенности жизнью через самовыражение
F13: Развитие лидерских качеств
F14: Расширение участия в социальной деятельности
F15: Расширение потенциала
... F21: Поддержка людей в том, чтобы позитивно встречать риски

Sheet По секторам
A1: Экономика | B1: Прямой вклад в экономическое развитие как поставщика услуг | C1: Расширение возможностей получения знаний (по сферам/отраслям знаний) | D1: Мотивация активного времяпровождения | E1: Формирование отношения к бережливости, уважения к наследию, созданному помимо тебя, включая природу | F1: Услуги для людей с ограниченными возможностями | G1: Консолидация сообщества | H1: Городская реновация | I1: чувство связи с прошлым (история, наследие, идентичность)
A2: Образование | B2: Прямой и косвенный вклад в занятость | C2: Развитие когнитивных способностей | D2: Влияние на психическое самочувствие, психологическую реабилитацию | E2: Экологическая осведомленность / Повышение экологических знаний, осведомленность об экологических проблемах | F2: «Точка» формирования соц. Ответственности | G2: Формирование гордости, уважительного отношения к месту проживания | H2: Привлекательность региона | I2: уважение к разнообразию и непохожести
A3: Здоровье | B3: Повышение привлекательности для туристов (иностранных и из других регионов) | C3: Влияние на уровень грамотности и успеваемость молодежи | D3: Воздействие на отношение к своему здоровью | E3: Формирование отношения к разнообразию | F3: Система услуг для пожилых / для людей с ограниченными возможностями | G3: Развитие гражданского участия, вовлечённости, ответственности, местного политического процесса | H3: Доступность среды | I3: опыт переживания эстетического удовольствия
A4: Экология | B4: Вклад в креативную экономику, творческие навыки предпринимателей | C4: Поощрение взрослых использовать возможности образования и профессиональной подготовки на протяжении всей жизни | D4: Мотивация путешествий и активного времяпровождения | E4: Позитивное ощущение места | F4: Снижение стигматизации и маргинализации | G4: Привлекательность «точки» культуры для творческих людей и профессий, влияние на состав населения и за счёт этого на благополучие территории | H4: Эстетические качества среды | I4: выражение общих смыслов (включая духовную, трансперсональную связь)
A5: Социальная сфера | B5: Влияние на малый ремесленный бизнес | E5: Позитивная связь с миром природы | F5: Равенство возможностей | G5: Изменение благополучия локального сообщества / рост социального капитала | H5: Освоенность общественных зон | I5: стимуляция креативности
A6: Местное развитие | B6: Спрос на инженерно-технические решения и инновационные технологии (климатическая техника, охранная техника и безопасность, освещение, системы хранения, противодействие правонарушениям в сфере культуры) | E6: Экологичные привычки и поведение | F6: Помощь правонарушителям и потерпевшим в решении проблемы преступности | G6: Чувство принадлежности, причастности, вовлеченности | H6: Безопасность среды | I6: возможность творческого или символического самовыражения
A7: Городская среда | B7: Влияние на стоимость близлежащей недвижимости | E7: Снижение антропогенного воздействия | F7: Альтернативная сфера досуга, сужающая «пространство» для асоциальной и противоправной деятельности | G7: Содействие развитию партнерства | H7: Вовлечение местных жителей в процесс возрождения территорий | I7: развитие сообщества художников, креативных индустрий,
A8: Культура | B8: Влияние на защиту авторских прав и историческую доказательность | E8: Зеленый менеджмент и девелопмент среды | G8: Уменьшение изоляции, через обретение новых дружеских связей | H8: Вызов традиционному способу предоставления услуг | I8: возможности самовыражения членов локального сообщества через вовлечение в творческие практики
B9: Конкурентоспособность региона | G9: Развитие контактов между поколениями | H9: Содействие созданию более спокойной атмосферы в медицинских центрах | I9: практики рефлексии
H10: Помощь в изменении имиджа общественных организаций или государственных органов

Sheet по секторам адекват
A1: Экономика | B1: Образование | C1: Здоровье | D1: Экология | E1: Социальная сфера | F1: Местное развитие | G1: Городская среда | H1: Культура
A2: Прямой вклад в экономическое развитие как поставщика услуг | B2: Расширение возможностей получения знаний (по сферам/отраслям знаний) | C2: Мотивация активного времяпровождения | D2: Формирование отношения к бережливости, уважения к наследию, созданному помимо тебя, включая природу | E2: Услуги для людей с ограниченными возможностями | F2: Консолидация сообщества | G2: Городская реновация | H2: чувство связи с прошлым (история, наследие, идентичность)
A3: Прямой и косвенный вклад в занятость | B3: Развитие когнитивных способностей | C3: Влияние на психическое самочувствие, психологическую реабилитацию | D3: Экологическая осведомленность / Повышение экологических знаний, осведомленность об экологических проблемах | E3: «Точка» формирования соц. Ответственности | F3: Формирование гордости, уважительного отношения к месту проживания | G3: Привлекательность региона | H3: уважение к разнообразию и непохожести
A4: Повышение привлекательности для туристов (иностранных и из других регионов) | B4: Влияние на уровень грамотности и успеваемость молодежи | C4: Воздействие на отношение к своему здоровью | D4: Формирование отношения к разнообразию | E4: Система услуг для пожилых / для людей с ограниченными возможностями | F4: Развитие гражданского участия, вовлечённости, ответственности, местного политического процесса | G4: Доступность среды | H4: опыт переживания эстетического удовольствия
A5: Вклад в креативную экономику, творческие навыки предпринимателей | B5: Поощрение взрослых использовать возможности образования и профессиональной подготовки на протяжении всей жизни | C5: Мотивация путешествий и активного времяпровождения | D5: Позитивное ощущение места | E5: Снижение стигматизации и маргинализации | F5: Привлекательность «точки» культуры для творческих людей и профессий, влияние на состав населения и за счёт этого на благополучие территории | G5: Эстетические качества среды | H5: выражение общих смыслов (включая духовную, трансперсональную связь)
A6: Влияние на малый ремесленный бизнес | D6: Позитивная связь с миром природы | E6: Равенство возможностей | F6: Изменение благополучия локального сообщества / рост социального капитала | G6: Освоенность общественных зон | H6: стимуляция креативности
A7: Спрос на инженерно-технические решения и инновационные технологии (климатическая техника, охранная техника и безопасность, освещение, системы хранения, противодействие правонарушениям в сфере культуры) | D7: Экологичные привычки и поведение | E7: Помощь правонарушителям и потерпевшим в решении проблемы преступности | F7: Чувство принадлежности, причастности, вовлеченности | G7: Безопасность среды | H7: возможность творческого или символического самовыражения
A8: Влияние на стоимость близлежащей недвижимости | D8: Снижение антропогенного воздействия | E8: Альтернативная сфера досуга, сужающая «пространство» для асоциальной и противоправной деятельности | F8: Содействие развитию партнерства | G8: Вовлечение местных жителей в процесс возрождения территорий | H8: развитие сообщества художников, креативных индустрий,
A9: Влияние на защиту авторских прав и историческую доказательность | D9: Зеленый менеджмент и девелопмент среды | F9: Уменьшение изоляции, через обретение новых дружеских связей | G9: Вызов традиционному способу предоставления услуг | H9: возможности самовыражения членов локального сообщества через вовлечение в творческие практики
A10: Конкурентоспособность региона | F10: Развитие контактов между поколениями | G10: Содействие созданию более спокойной атмосферы в медицинских центрах | H10: практики рефлексии
G11: Помощь в изменении имиджа общественных организаций или государственных органов

Sheet Лист9
A1: «Точка» формирования соц. Ответственности
A2: Активизация культурного потенциала территорий | B2: Права и свободы человека
A3: Альтернативная сфера досуга, сужающая «пространство» для асоциальной и противоправной деятельности
A4: Безопасность среды | B4: Справедливость
A5: Вдохновение
A6: Вдохновение новыми идеями
A7: Вклад в креативную экономику, творческие навыки предпринимателей
A8: Вклад в личностное развитие | B8: Патриотизм, Гражданственность, Высокие нравственные идеалы, Приоритет духовного над материальным, Взаимопомощь и взаимоуважение
A9: Вклад в развитие взаимодействия и партнерства
A10: Вклад в экономику | B10: Служение Отечеству и ответственность за его судьбу
A11: Вклад в экономику региона | B11: Служение Отечеству и ответственность за его судьбу
A12: Вклад в экономическое благополучие региона | B12: Служение Отечеству и ответственность за его судьбу
A13: Владение русским литературным языком, знание истории страны | B13: Историческая память и преемственность поколений
A14: Влияние на защиту авторских прав и историческую доказательность
A15: Влияние на малый ремесленный бизнес
A16: Влияние на психическое самочувствие, психологическую реабилитацию
A17: Влияние на стоимость близлежащей недвижимости
A18: Влияние на уровень грамотности и успеваемость молодежи
A19: Вовлечение жителей в процесс развития региона | B19: Служение Отечеству и ответственность за его судьбу
A20: Вовлечение местных жителей в процесс возрождения территорий
A21: Воздействие на отношение к своему здоровью
A22: возможности самовыражения членов локального сообщества через вовлечение в творческие практики
A23: Возможности самореализации | B23: Достоинство
A24: Возможность отвлечения от повседневных забот
A25: возможность творческого или символического самовыражения
A26: Вызов традиционному способу предоставления услуг
A27: выражение общих смыслов (включая духовную, трансперсональную связь)
A28: Гармонизация социально-экономического развития регионов страны, особенно малых городов и сельских поселений | B28: Служение Отечеству и ответственность за его судьбу
A29: Гармонизация социально-экономического развития регионов страны, особенно малых городов и сельских поселений | B29: Единство народов России
A30: Городская реновация
A31: Достоинство
A32: Доступность среды | B32: Справедливость
A33: Зеленый менеджмент и девелопмент среды
A34: Изменение благополучия локального сообщества / рост социального капитала
A35: Изменение знаний и навыков | B35: Жизнь
A36: Изменение отношения к культуре, обществу, наследию, экологии … | B36: Патриотизм, Гражданственность, Высокие нравственные идеалы, Историческая память и преемственность поколений
A37: Изменение отношения к культуре, обществу, наследию, экологии … | B37: Патриотизм
A38: Изменение отношения к культуре, обществу, наследию, экологии … | B38: Гражданственность
A39: Изменение поведения | B39: Приоритет духовного над материальным
A40: Изменение понимания/ ожиданий возможностей самореализации | B40: Взаимопомощь и взаимоуважение
...

Sheet По благам
A2: Частные блага | B2: Инструментальные | C2: Повышение уровня знаний | D2: Вдохновение | E2: Расширение участия | F2: Расширенная способность к сопереживанию | G2: Развитие партнерств | H2: Создание социальных связей
A3: Частные блага с общественным эффектом | B3: Внутренние | C3: Улучшенные навыки коммуникации | D3: Удовольствие | E3: Повышение самоэффективности | F3: Расширенная способность к саморефлексии | G3: Содействие развитию сообщества | H3: Проявление общественной значимости
A4: Общественные блага | D4: Достоинство | E4: Повышение навыков обучения | F4: Когнитивный рост | G4: Вклад в экономику региона | H4: Капитализация культурных организаций и проектов
F5: Формирование идентичности | G5: Развитие социального капитала | H5: Сохранение наследия
F6: Возможность отвлечения от повседневных забот

Sheet Лист1 (копия)
A2: Подход | D2: Область влияния | G2: Результат
A3: Фокус на социокультурных благах | B3: =IF(IFERROR(SEARCH("благополучателе", A3) > 0, FALSE), "Фокуснаблагополучателе", IF(IFERROR(SEARCH("секторе", A3) > 0, FALSE), "Фокуснасекторе", IF(IFERROR(SEARCH("благах", A3) > 0, FALSE), "Фокуснаблагах",""))) -> Фокуснаблагах | C3: {=INDIRECT(B3)} | D3: Частные блага | E3: =IF(IFERROR(SEARCH("публика", D3) > 0, FALSE), "ФБСообщество", IF(IFERROR(SEARCH("люди", D3) > 0, FALSE), "ФБЛюди", IF(IFERROR(SEARCH("семьи", D3) > 0, FALSE), "ФБСемьи", IF(IFERROR(SEARCH("правительство", D3) > 0, FALSE), "ФББизнес", IF(IFERROR(SEARCH("команда", D3) > 0, FALSE), "ФБКоманда", IF(IFERROR(SEARCH("экономика", D3) > 0, FALSE), "ФСЭкономика", IF(IFERROR(SEARCH("образование", D3) > 0, FALSE), "ФСОбразование",IF(IFERROR(SEARCH("здоровье", D3) > 0, FALSE), "ФСЗдоровье",IF(IFERROR(SEARCH("экология", D3) > 0, FALSE), "ФСЭкология", IF(IFERROR(SEARCH("сфера", D3) > 0, FALSE), "ФССоциальнаясфера", IF(IFERROR(SEARCH("развитие", D3) > 0, FALSE), "ФСМестноеразвитие", IF(IFERROR(SEARCH("среда", D3) > 0, FALSE), "ФСГородскаясреда",IF(IFERROR(SEARCH("культура", D3) > 0, FALSE), "ФСКультура", IF(IFERROR(SEARCH("блага", D3) > 0, FALSE), "ФБлага","")))))))))))))) -> ФБлага | F3: {=INDIRECT(E3)}
C4: Частные блага | F4: Инструментальные
C5: Частные блага с общественным эффектом | F5: Внутренние
C6: Общественные блага

Sheet По благополучателям адекват
A1: Отдельные люди | B1: Семьи и социальные группы | C1: Сообщество, общественность, широкая публика | D1: Бизнес-сообщество, правительство, экономические субъекты | E1: Социокультурная институция / команда
A2: Вклад в личностное развитие | B2: Обеспечение условий для развлечений, удовольствий, радости | C2: Расширение участия | D2: Вклад в экономику | E2: Содействие ведению текущей деятельности культурных институций
A3: Развитие эмоционального интеллекта | B3: Обеспечение возможности отвлечения от повседневных забот | C3: Сохранение наследия | D3: Вклад в развитие взаимодействия и партнерства | E3: Капитализация культурных институций
A4: Повышение самоэффективности, | C4: Повышение уровня знаний в обществе
A5: Повышение навыков обучения | C5: Укрепление социального капитала
A6: Изменение понимания/ ожиданий возможностей самореализации | C6: Содействие развитию сообщества
A7: Изменение отношения к культуре, обществу, наследию, экологии … | C7: Формирование идентичности и узнаваемости
A8: Изменение знаний и навыков
A9: Изменение поведения
A10: Повышение общей удовлетворенности жизнью через самовыражение
A11: Развитие лидерских качеств
A12: Расширение участия в социальной деятельности
A13: Расширение потенциала
A14: Повышение эффектов благополучия (стресс, самооценка, уверенность, удовольствие…)
A15: Изменение чувства безопасности
A16: Изменение чувства валидированности (не стигматизированности)
A17: Вдохновение новыми идеями
A18: Содействие людям в исследовании своих ценностей, смыслов и мечтаний
A19: Поддержка людей в том, чтобы позитивно встречать риски

Sheet Показатели
A1: Результат | B1: Ценности | C1: Показатель 2 | D1: Показатель 3
A2: «Точка» формирования соц. Ответственности | B2: Служение Отечеству и ответственность за его судьбу, Гражданственность | C2: Доля участников, включившихся в волонтерские/шефские программы проекта на постоянной основе (спустя 3 месяца). | D2: Количество социальных инициатив, запущенных участниками проекта для местного сообщества без внешнего финансирования.
A3: Активизация культурного потенциала территорий | B3: Права и свободы человека | C3: Количество вновь выявленных объектов нематериального культурного наследия (обрядов, песен, ремесел) с участием местных жителей. | D3: Рост туристического потока (экскурсантов) на ранее не популярные локации территории.
A4: Альтернативная сфера досуга, сужающая «пространство» для асоциальной и противоправной деятельности | B4: Жизнь, Достоинство | C4: Снижение числа обращений в полицию по делам о правонарушениях в районе проведения мероприятий в вечернее время (в сравнении с прошлым годом). | D4: Охват целевой «трудной» аудитории (количество подростков из группы риска, регулярно посещающих площадку).
A5: Безопасность среды | B5: Справедливость | C5: Количество выявленных и устраненных архитектурно-конструктивных дефектов (разбитые ступени, темные зоны) силами проектной команды. | D5: Индекс субъективного ощущения безопасности (по результатам опроса местных жителей, % чувствующих себя в безопасности).
A6: Вдохновение | B6: Жизнь, Приоритет духовного над материальным | C6: Количество творческих работ (стихов, картин, эссе), созданных участниками под впечатлением от проекта. | D6: Количество участников, изменивших свой ежедневный график/род занятий для продолжения деятельности в сфере культуры (самореализация).
A7: Вдохновение новыми идеями | B7: Созидательный труд | C7: Количество стартапов или социальных проектов, поданных на грантовые конкурсы, чья концепция родилась на площадках проекта. | D7: Количество междисциплинарных коллабораций (музыка+наука, театр+IT), созданных по инициативе участников.
A8: Вклад в креативную экономику, творческие навыки предпринимателей | B8: Жизнь, Созидательный труд | C8: Количество предпринимателей, прошедших обучение и внедривших креативные инструменты (сторителлинг, брендинг) в свои бизнес-процессы. | D8: Рост среднего чека в творческих мастерских участников проекта за счет внедрения новых продуктовых линеек.
A9: Вклад в личностное развитие | B9: Патриотизм, Гражданственность, Высокие нравственные идеалы, Приоритет духовного над материальным, Взаимопомощь и взаимоуважение | C9: Положительная динамика в уровне эмоционального интеллекта и самооценки (по методикам опросников «до/после»). | D9: Количество участников, получивших новые профессиональные компетенции (сертификаты, навыки) и применивших их на основной работе.
A10: Вклад в развитие взаимодействия и партнерства | B10: Взаимопомощь и взаимоуважение | C10: Количество новых устойчивых партнерств (Меморандумов/договоров) между НКО, бизнесом и властью, заключенных благодаря проекту. | D10: Количество совместных мероприятий, проведенных в тандеме с другими учреждениями культуры района.
A11: Вклад в экономику | B11: Служение Отечеству и ответственность за его судьбу | C11: Объем внебюджетных средств (спонсорских, грантовых), привлеченных в локальный оборот на реализацию проекта. | D11: Количество созданных временных рабочих мест для местных жителей (организаторы, волонтеры, технический персонал).
A12: Вклад в экономику региона | B12: Служение Отечеству и ответственность за его судьбу | C12: Увеличение налоговых поступлений от субъектов МСП, задействованных в проекте (в календарный период). | D12: Рост инвестиционной привлекательности района (количество запросов от инвесторов после PR-кампании проекта).
... A134: Cпособность понимать и ценить искусство и культуру | B134: Приоритет духовного над материальным | C134: Рост правильных интерпретаций смыслов в арт-объектах (тест). | D134: Количество посещений музеев/выставок после проекта.

Sheet Экспертиза
A1: Результат | B1: Отмеченные ценности | C1: Предложения по изменению
A2: ='Показатели'!A2 -> «Точка» формирования соц. Ответственности | B2: ='Показатели'!B2 -> Служение Отечеству и ответственность за его судьбу, Гражданственность
A3: ='Показатели'!A3 -> Активизация культурного потенциала территорий | B3: ='Показатели'!B3 -> Права и свободы человека
A4: ='Показатели'!A4 -> Альтернативная сфера досуга, сужающая «пространство» для асоциальной и противоправной деятельности | B4: ='Показатели'!B4 -> Жизнь, Достоинство
A5: ='Показатели'!A5 -> Безопасность среды | B5: ='Показатели'!B5 -> Справедливость
A6: ='Показатели'!A6 -> Вдохновение | B6: ='Показатели'!B6 -> Жизнь, Приоритет духовного над материальным
A7: ='Показатели'!A7 -> Вдохновение новыми идеями | B7: ='Показатели'!B7 -> Созидательный труд
A8: ='Показатели'!A8 -> Вклад в креативную экономику, творческие навыки предпринимателей | B8: ='Показатели'!B8 -> Жизнь, Созидательный труд
A9: ='Показатели'!A9 -> Вклад в личностное развитие | B9: ='Показатели'!B9 -> Патриотизм, Гражданственность, Высокие нравственные идеалы, Приоритет духовного над материальным, Взаимопомощь и взаимоуважение
A10: ='Показатели'!A10 -> Вклад в развитие взаимодействия и партнерства | B10: ='Показатели'!B10 -> Взаимопомощь и взаимоуважение
A11: ='Показатели'!A11 -> Вклад в экономику | B11: ='Показатели'!B11 -> Служение Отечеству и ответственность за его судьбу
A12: ='Показатели'!A12 -> Вклад в экономику региона | B12: ='Показатели'!B12 -> Служение Отечеству и ответственность за его судьбу
A13: ='Показатели'!A13 -> Вклад в экономическое благополучие региона | B13: ='Показатели'!B13 -> Служение Отечеству и ответственность за его судьбу
... A29: ='Показатели'!A29 -> Гармонизация социально-экономического развития регионов страны, особенно малых городов и сельских поселений | B29: ='Показатели'!B29 -> Служение Отечеству и ответственность за его судьбу, Единство народов России, Патриотизм
A30: =#REF! -> #REF! | B30: =#REF! -> #REF!
A31: ='Показатели'!A30 -> Городская реновация | B31: ='Показатели'!B30 -> Служение Отечеству и ответственность за его судьбу
A32: ='Показатели'!A31 -> Достоинство | B32: ='Показатели'!B31 -> Достоинство
A33: ='Показатели'!A32 -> Доступность среды | B33: ='Показатели'!B32 -> Справедливость
A34: ='Показатели'!A33 -> Зеленый менеджмент и девелопмент среды | B34: ='Показатели'!B33 -> Служение Отечеству и ответственность за его судьбу
A35: ='Показатели'!A34 -> Изменение благополучия локального сообщества / рост социального капитала | B35: ='Показатели'!B34 -> Жизнь, Достоинство, Права и свободы человека
A36: ='Показатели'!A35 -> Изменение знаний и навыков | B36: ='Показатели'!B35 -> Жизнь
A37: ='Показатели'!A36 -> Изменение отношения к культуре, обществу, наследию, экологии … | B37: ='Показатели'!B36 -> Патриотизм, Гражданственность, Высокие нравственные идеалы, Историческая память и преемственность поколений
A38: =#REF! -> #REF! | B38: =#REF! -> #REF!
A39: =#REF! -> #REF! | B39: =#REF! -> #REF!
A40: ='Показатели'!A37 -> Изменение поведения | B40: ='Показатели'!B37 -> Приоритет духовного над материальным
A41: ='Показатели'!A38 -> Изменение понимания/ ожиданий возможностей самореализации | B41: ='Показатели'!B38 -> Взаимопомощь и взаимоуважение
A42: ='Показатели'!A39 -> Изменение чувства безопасности | B42: ='Показатели'!B39 -> Права и свободы человека
A43: =#REF! -> #REF! | B43: =#REF! -> #REF!
A44: ='Показатели'!A40 -> Изменение чувства валидированности (не стигматизированности) | B44: ='Показатели'!B40 -> Права и свободы человека, Достоинство, Гуманизм, Милосердие, Взаимопомощь и взаимоуважение, Справедливость
A45: ='Показатели'!A41 -> Капитализация культурных институций | B45: ='Показатели'!B41 -> Созидательный труд
A46: ='Показатели'!A42 -> Капитализация культурных организаций и проектов | B46: ='Показатели'!B42 -> Созидательный труд
A47: ='Показатели'!A43 -> Качественный рост культурных и досуговых запросов граждан, в том числе в отношении медиапродукции | B47: ='Показатели'!B43 -> Высокие нравственные идеалы, Приоритет духовного над материальным
A48: ='Показатели'!A44 -> Когнитивный рост | B48: ='Показатели'!B44 -> Жизнь
A49: ='Показатели'!A45 -> Конкурентоспособность региона | B49: ='Показатели'!B45 -> Служение Отечеству и ответственность за его судьбу
A50: ='Показатели'!A46 -> Консолидация местного сообщества | B50: ='Показатели'!B46 -> Гражданственность, Служение Отечеству и ответственность за его судьбу, Коллективизм, Историческая память и преемственность поколений
A51: =#REF! -> #REF! | B51: =#REF! -> #REF!
A52: ='Показатели'!A47 -> Мотивация активного времяпровождения | B52: ='Показатели'!B47 -> Жизнь
A53: ='Показатели'!A48 -> Мотивация активного образа жизни | B53: ='Показатели'!B48 -> Жизнь
A54: ='Показатели'!A49 -> Мотивация путешествий и активного времяпровождения | B54: ='Показатели'!B49 -> Жизнь
A55: ='Показатели'!A50 -> Национальная идентичность / развитие межнациональных / межкультурных связей | B55: ='Показатели'!B50 -> Единство народов России
...
